Internal Server Error: /student/
Traceback (most recent call last):
  File "C:\home\React\djnago_rest_framework\Final_project4_backend\venv\Lib\site-packages\django\core\handlers\exception.py", line 55, in inner
    response = get_response(request)
               ^^^^^^^^^^^^^^^^^^^^^
  File "C:\home\React\djnago_rest_framework\Final_project4_backend\venv\Lib\site-packages\django\core\handlers\base.py", line 197, in _get_response
    response = wrapped_callback(request, *callback_args, **callback_kwargs)
               ^^^^^^^^^^^^^^^^^^^^^^^^^^^^^^^^^^^^^^^^^^^^^^^^^^^^^^^^^^^^
  File "C:\home\React\djnago_rest_framework\Final_project4_backend\venv\Lib\site-packages\django\views\decorators\csrf.py", line 65, in _view_wrapper
    return view_func(request, *args, **kwargs)
           ^^^^^^^^^^^^^^^^^^^^^^^^^^^^^^^^^^^
  File "C:\home\React\djnago_rest_framework\Final_project4_backend\venv\Lib\site-packages\django\views\generic\base.py", line 104, in view
    return self.dispatch(request, *args, **kwargs)
           ^^^^^^^^^^^^^^^^^^^^^^^^^^^^^^^^^^^^^^^
  File "C:\home\React\djnago_rest_framework\Final_project4_backend\venv\Lib\site-packages\rest_framework\views.py", line 509, in dispatch
    response = self.handle_exception(exc)
               ^^^^^^^^^^^^^^^^^^^^^^^^^^
  File "C:\home\React\djnago_rest_framework\Final_project4_backend\venv\Lib\site-packages\rest_framework\views.py", line 469, in handle_exception
    self.raise_uncaught_exception(exc)
  File "C:\home\React\djnago_rest_framework\Final_project4_backend\venv\Lib\site-packages\rest_framework\views.py", line 480, in raise_uncaught_exception
    raise exc
  File "C:\home\React\djnago_rest_framework\Final_project4_backend\venv\Lib\site-packages\rest_framework\views.py", line 506, in dispatch
    response = handler(request, *args, **kwargs)
               ^^^^^^^^^^^^^^^^^^^^^^^^^^^^^^^^^
  File "C:\home\React\djnago_rest_framework\Final_project4_backend\two_factor_auth_project\crud_app\views.py", line 25, in post
    logger.info(f'Student Added at time: {datetime.datetime.now()}')
                                         ^^^^^^^^^^^^^^^^^
AttributeError: type object 'datetime.datetime' has no attribute 'datetime'
Internal Server Error: /register/
Traceback (most recent call last):
  File "C:\home\React\djnago_rest_framework\Final_project4_backend\venv\Lib\site-packages\django\core\handlers\exception.py", line 55, in inner
    response = get_response(request)
               ^^^^^^^^^^^^^^^^^^^^^
  File "C:\home\React\djnago_rest_framework\Final_project4_backend\venv\Lib\site-packages\django\core\handlers\base.py", line 197, in _get_response
    response = wrapped_callback(request, *callback_args, **callback_kwargs)
               ^^^^^^^^^^^^^^^^^^^^^^^^^^^^^^^^^^^^^^^^^^^^^^^^^^^^^^^^^^^^
  File "C:\home\React\djnago_rest_framework\Final_project4_backend\venv\Lib\site-packages\django\views\decorators\csrf.py", line 65, in _view_wrapper
    return view_func(request, *args, **kwargs)
           ^^^^^^^^^^^^^^^^^^^^^^^^^^^^^^^^^^^
  File "C:\home\React\djnago_rest_framework\Final_project4_backend\venv\Lib\site-packages\django\views\generic\base.py", line 104, in view
    return self.dispatch(request, *args, **kwargs)
           ^^^^^^^^^^^^^^^^^^^^^^^^^^^^^^^^^^^^^^^
  File "C:\home\React\djnago_rest_framework\Final_project4_backend\venv\Lib\site-packages\rest_framework\views.py", line 509, in dispatch
    response = self.handle_exception(exc)
               ^^^^^^^^^^^^^^^^^^^^^^^^^^
  File "C:\home\React\djnago_rest_framework\Final_project4_backend\venv\Lib\site-packages\rest_framework\views.py", line 469, in handle_exception
    self.raise_uncaught_exception(exc)
  File "C:\home\React\djnago_rest_framework\Final_project4_backend\venv\Lib\site-packages\rest_framework\views.py", line 480, in raise_uncaught_exception
    raise exc
  File "C:\home\React\djnago_rest_framework\Final_project4_backend\venv\Lib\site-packages\rest_framework\views.py", line 506, in dispatch
    response = handler(request, *args, **kwargs)
               ^^^^^^^^^^^^^^^^^^^^^^^^^^^^^^^^^
  File "C:\home\React\djnago_rest_framework\Final_project4_backend\two_factor_auth_project\auth_app\views.py", line 21, in post
    token = RefreshToken.for_user(email).access_token
            ^^^^^^^^^^^^^^^^^^^^^^^^^^^^
  File "C:\home\React\djnago_rest_framework\Final_project4_backend\venv\Lib\site-packages\rest_framework_simplejwt\tokens.py", line 203, in for_user
    user_id = getattr(user, api_settings.USER_ID_FIELD)
              ^^^^^^^^^^^^^^^^^^^^^^^^^^^^^^^^^^^^^^^^^
AttributeError: 'str' object has no attribute 'id'
Internal Server Error: /register/
Traceback (most recent call last):
  File "C:\home\React\djnago_rest_framework\Final_project4_backend\venv\Lib\site-packages\django\core\handlers\exception.py", line 55, in inner
    response = get_response(request)
               ^^^^^^^^^^^^^^^^^^^^^
  File "C:\home\React\djnago_rest_framework\Final_project4_backend\venv\Lib\site-packages\django\core\handlers\base.py", line 197, in _get_response
    response = wrapped_callback(request, *callback_args, **callback_kwargs)
               ^^^^^^^^^^^^^^^^^^^^^^^^^^^^^^^^^^^^^^^^^^^^^^^^^^^^^^^^^^^^
  File "C:\home\React\djnago_rest_framework\Final_project4_backend\venv\Lib\site-packages\django\views\decorators\csrf.py", line 65, in _view_wrapper
    return view_func(request, *args, **kwargs)
           ^^^^^^^^^^^^^^^^^^^^^^^^^^^^^^^^^^^
  File "C:\home\React\djnago_rest_framework\Final_project4_backend\venv\Lib\site-packages\django\views\generic\base.py", line 104, in view
    return self.dispatch(request, *args, **kwargs)
           ^^^^^^^^^^^^^^^^^^^^^^^^^^^^^^^^^^^^^^^
  File "C:\home\React\djnago_rest_framework\Final_project4_backend\venv\Lib\site-packages\rest_framework\views.py", line 509, in dispatch
    response = self.handle_exception(exc)
               ^^^^^^^^^^^^^^^^^^^^^^^^^^
  File "C:\home\React\djnago_rest_framework\Final_project4_backend\venv\Lib\site-packages\rest_framework\views.py", line 469, in handle_exception
    self.raise_uncaught_exception(exc)
  File "C:\home\React\djnago_rest_framework\Final_project4_backend\venv\Lib\site-packages\rest_framework\views.py", line 480, in raise_uncaught_exception
    raise exc
  File "C:\home\React\djnago_rest_framework\Final_project4_backend\venv\Lib\site-packages\rest_framework\views.py", line 506, in dispatch
    response = handler(request, *args, **kwargs)
               ^^^^^^^^^^^^^^^^^^^^^^^^^^^^^^^^^
  File "C:\home\React\djnago_rest_framework\Final_project4_backend\two_factor_auth_project\auth_app\views.py", line 21, in post
    token = RefreshToken.for_user(email).access_token
            ^^^^^^^^^^^^^^^^^^^^^^^^^^^^
  File "C:\home\React\djnago_rest_framework\Final_project4_backend\venv\Lib\site-packages\rest_framework_simplejwt\tokens.py", line 203, in for_user
    user_id = getattr(user, api_settings.USER_ID_FIELD)
              ^^^^^^^^^^^^^^^^^^^^^^^^^^^^^^^^^^^^^^^^^
AttributeError: 'str' object has no attribute 'id'
Internal Server Error: /register/
Traceback (most recent call last):
  File "C:\home\React\djnago_rest_framework\Final_project4_backend\venv\Lib\site-packages\django\core\handlers\exception.py", line 55, in inner
    response = get_response(request)
               ^^^^^^^^^^^^^^^^^^^^^
  File "C:\home\React\djnago_rest_framework\Final_project4_backend\venv\Lib\site-packages\django\core\handlers\base.py", line 197, in _get_response
    response = wrapped_callback(request, *callback_args, **callback_kwargs)
               ^^^^^^^^^^^^^^^^^^^^^^^^^^^^^^^^^^^^^^^^^^^^^^^^^^^^^^^^^^^^
  File "C:\home\React\djnago_rest_framework\Final_project4_backend\venv\Lib\site-packages\django\views\decorators\csrf.py", line 65, in _view_wrapper
    return view_func(request, *args, **kwargs)
           ^^^^^^^^^^^^^^^^^^^^^^^^^^^^^^^^^^^
  File "C:\home\React\djnago_rest_framework\Final_project4_backend\venv\Lib\site-packages\django\views\generic\base.py", line 104, in view
    return self.dispatch(request, *args, **kwargs)
           ^^^^^^^^^^^^^^^^^^^^^^^^^^^^^^^^^^^^^^^
  File "C:\home\React\djnago_rest_framework\Final_project4_backend\venv\Lib\site-packages\rest_framework\views.py", line 509, in dispatch
    response = self.handle_exception(exc)
               ^^^^^^^^^^^^^^^^^^^^^^^^^^
  File "C:\home\React\djnago_rest_framework\Final_project4_backend\venv\Lib\site-packages\rest_framework\views.py", line 469, in handle_exception
    self.raise_uncaught_exception(exc)
  File "C:\home\React\djnago_rest_framework\Final_project4_backend\venv\Lib\site-packages\rest_framework\views.py", line 480, in raise_uncaught_exception
    raise exc
  File "C:\home\React\djnago_rest_framework\Final_project4_backend\venv\Lib\site-packages\rest_framework\views.py", line 506, in dispatch
    response = handler(request, *args, **kwargs)
               ^^^^^^^^^^^^^^^^^^^^^^^^^^^^^^^^^
  File "C:\home\React\djnago_rest_framework\Final_project4_backend\two_factor_auth_project\auth_app\views.py", line 21, in post
    token = RefreshToken.for_user(email).access_token
            ^^^^^^^^^^^^^^^^^^^^^^^^^^^^
  File "C:\home\React\djnago_rest_framework\Final_project4_backend\venv\Lib\site-packages\rest_framework_simplejwt\tokens.py", line 203, in for_user
    user_id = getattr(user, api_settings.USER_ID_FIELD)
              ^^^^^^^^^^^^^^^^^^^^^^^^^^^^^^^^^^^^^^^^^
AttributeError: 'str' object has no attribute 'id'
Internal Server Error: /register/
Traceback (most recent call last):
  File "C:\home\React\djnago_rest_framework\Final_project4_backend\venv\Lib\site-packages\django\core\handlers\exception.py", line 55, in inner
    response = get_response(request)
               ^^^^^^^^^^^^^^^^^^^^^
  File "C:\home\React\djnago_rest_framework\Final_project4_backend\venv\Lib\site-packages\django\core\handlers\base.py", line 197, in _get_response
    response = wrapped_callback(request, *callback_args, **callback_kwargs)
               ^^^^^^^^^^^^^^^^^^^^^^^^^^^^^^^^^^^^^^^^^^^^^^^^^^^^^^^^^^^^
  File "C:\home\React\djnago_rest_framework\Final_project4_backend\venv\Lib\site-packages\django\views\decorators\csrf.py", line 65, in _view_wrapper
    return view_func(request, *args, **kwargs)
           ^^^^^^^^^^^^^^^^^^^^^^^^^^^^^^^^^^^
  File "C:\home\React\djnago_rest_framework\Final_project4_backend\venv\Lib\site-packages\django\views\generic\base.py", line 104, in view
    return self.dispatch(request, *args, **kwargs)
           ^^^^^^^^^^^^^^^^^^^^^^^^^^^^^^^^^^^^^^^
  File "C:\home\React\djnago_rest_framework\Final_project4_backend\venv\Lib\site-packages\rest_framework\views.py", line 509, in dispatch
    response = self.handle_exception(exc)
               ^^^^^^^^^^^^^^^^^^^^^^^^^^
  File "C:\home\React\djnago_rest_framework\Final_project4_backend\venv\Lib\site-packages\rest_framework\views.py", line 469, in handle_exception
    self.raise_uncaught_exception(exc)
  File "C:\home\React\djnago_rest_framework\Final_project4_backend\venv\Lib\site-packages\rest_framework\views.py", line 480, in raise_uncaught_exception
    raise exc
  File "C:\home\React\djnago_rest_framework\Final_project4_backend\venv\Lib\site-packages\rest_framework\views.py", line 506, in dispatch
    response = handler(request, *args, **kwargs)
               ^^^^^^^^^^^^^^^^^^^^^^^^^^^^^^^^^
  File "C:\home\React\djnago_rest_framework\Final_project4_backend\two_factor_auth_project\auth_app\views.py", line 30, in post
    send_mail(
  File "C:\home\React\djnago_rest_framework\Final_project4_backend\venv\Lib\site-packages\django\core\mail\__init__.py", line 88, in send_mail
    return mail.send()
           ^^^^^^^^^^^
  File "C:\home\React\djnago_rest_framework\Final_project4_backend\venv\Lib\site-packages\django\core\mail\message.py", line 300, in send
    return self.get_connection(fail_silently).send_messages([self])
           ^^^^^^^^^^^^^^^^^^^^^^^^^^^^^^^^^^^^^^^^^^^^^^^^^^^^^^^^
  File "C:\home\React\djnago_rest_framework\Final_project4_backend\venv\Lib\site-packages\django\core\mail\backends\smtp.py", line 128, in send_messages
    new_conn_created = self.open()
                       ^^^^^^^^^^^
  File "C:\home\React\djnago_rest_framework\Final_project4_backend\venv\Lib\site-packages\django\core\mail\backends\smtp.py", line 86, in open
    self.connection = self.connection_class(
                      ^^^^^^^^^^^^^^^^^^^^^^
  File "C:\Users\bobad\AppData\Local\Programs\Python\Python311\Lib\smtplib.py", line 255, in __init__
    (code, msg) = self.connect(host, port)
                  ^^^^^^^^^^^^^^^^^^^^^^^^
  File "C:\Users\bobad\AppData\Local\Programs\Python\Python311\Lib\smtplib.py", line 341, in connect
    self.sock = self._get_socket(host, port, self.timeout)
                ^^^^^^^^^^^^^^^^^^^^^^^^^^^^^^^^^^^^^^^^^^
  File "C:\Users\bobad\AppData\Local\Programs\Python\Python311\Lib\smtplib.py", line 312, in _get_socket
    return socket.create_connection((host, port), timeout,
           ^^^^^^^^^^^^^^^^^^^^^^^^^^^^^^^^^^^^^^^^^^^^^^^
  File "C:\Users\bobad\AppData\Local\Programs\Python\Python311\Lib\socket.py", line 826, in create_connection
    for res in getaddrinfo(host, port, 0, SOCK_STREAM):
               ^^^^^^^^^^^^^^^^^^^^^^^^^^^^^^^^^^^^^^^
  File "C:\Users\bobad\AppData\Local\Programs\Python\Python311\Lib\socket.py", line 961, in getaddrinfo
    for res in _socket.getaddrinfo(host, port, family, type, proto, flags):
               ^^^^^^^^^^^^^^^^^^^^^^^^^^^^^^^^^^^^^^^^^^^^^^^^^^^^^^^^^^^
socket.gaierror: [Errno 11001] getaddrinfo failed
Bad Request: /register/
Internal Server Error: /register/
Traceback (most recent call last):
  File "C:\home\React\djnago_rest_framework\Final_project4_backend\venv\Lib\site-packages\django\core\handlers\exception.py", line 55, in inner
    response = get_response(request)
               ^^^^^^^^^^^^^^^^^^^^^
  File "C:\home\React\djnago_rest_framework\Final_project4_backend\venv\Lib\site-packages\django\core\handlers\base.py", line 197, in _get_response
    response = wrapped_callback(request, *callback_args, **callback_kwargs)
               ^^^^^^^^^^^^^^^^^^^^^^^^^^^^^^^^^^^^^^^^^^^^^^^^^^^^^^^^^^^^
  File "C:\home\React\djnago_rest_framework\Final_project4_backend\venv\Lib\site-packages\django\views\decorators\csrf.py", line 65, in _view_wrapper
    return view_func(request, *args, **kwargs)
           ^^^^^^^^^^^^^^^^^^^^^^^^^^^^^^^^^^^
  File "C:\home\React\djnago_rest_framework\Final_project4_backend\venv\Lib\site-packages\django\views\generic\base.py", line 104, in view
    return self.dispatch(request, *args, **kwargs)
           ^^^^^^^^^^^^^^^^^^^^^^^^^^^^^^^^^^^^^^^
  File "C:\home\React\djnago_rest_framework\Final_project4_backend\venv\Lib\site-packages\rest_framework\views.py", line 509, in dispatch
    response = self.handle_exception(exc)
               ^^^^^^^^^^^^^^^^^^^^^^^^^^
  File "C:\home\React\djnago_rest_framework\Final_project4_backend\venv\Lib\site-packages\rest_framework\views.py", line 469, in handle_exception
    self.raise_uncaught_exception(exc)
  File "C:\home\React\djnago_rest_framework\Final_project4_backend\venv\Lib\site-packages\rest_framework\views.py", line 480, in raise_uncaught_exception
    raise exc
  File "C:\home\React\djnago_rest_framework\Final_project4_backend\venv\Lib\site-packages\rest_framework\views.py", line 506, in dispatch
    response = handler(request, *args, **kwargs)
               ^^^^^^^^^^^^^^^^^^^^^^^^^^^^^^^^^
  File "C:\home\React\djnago_rest_framework\Final_project4_backend\two_factor_auth_project\auth_app\views.py", line 32, in post
    send_mail(
  File "C:\home\React\djnago_rest_framework\Final_project4_backend\venv\Lib\site-packages\django\core\mail\__init__.py", line 88, in send_mail
    return mail.send()
           ^^^^^^^^^^^
  File "C:\home\React\djnago_rest_framework\Final_project4_backend\venv\Lib\site-packages\django\core\mail\message.py", line 300, in send
    return self.get_connection(fail_silently).send_messages([self])
           ^^^^^^^^^^^^^^^^^^^^^^^^^^^^^^^^^^^^^^^^^^^^^^^^^^^^^^^^
  File "C:\home\React\djnago_rest_framework\Final_project4_backend\venv\Lib\site-packages\django\core\mail\backends\smtp.py", line 128, in send_messages
    new_conn_created = self.open()
                       ^^^^^^^^^^^
  File "C:\home\React\djnago_rest_framework\Final_project4_backend\venv\Lib\site-packages\django\core\mail\backends\smtp.py", line 86, in open
    self.connection = self.connection_class(
                      ^^^^^^^^^^^^^^^^^^^^^^
  File "C:\Users\bobad\AppData\Local\Programs\Python\Python311\Lib\smtplib.py", line 255, in __init__
    (code, msg) = self.connect(host, port)
                  ^^^^^^^^^^^^^^^^^^^^^^^^
  File "C:\Users\bobad\AppData\Local\Programs\Python\Python311\Lib\smtplib.py", line 341, in connect
    self.sock = self._get_socket(host, port, self.timeout)
                ^^^^^^^^^^^^^^^^^^^^^^^^^^^^^^^^^^^^^^^^^^
  File "C:\Users\bobad\AppData\Local\Programs\Python\Python311\Lib\smtplib.py", line 312, in _get_socket
    return socket.create_connection((host, port), timeout,
           ^^^^^^^^^^^^^^^^^^^^^^^^^^^^^^^^^^^^^^^^^^^^^^^
  File "C:\Users\bobad\AppData\Local\Programs\Python\Python311\Lib\socket.py", line 826, in create_connection
    for res in getaddrinfo(host, port, 0, SOCK_STREAM):
               ^^^^^^^^^^^^^^^^^^^^^^^^^^^^^^^^^^^^^^^
  File "C:\Users\bobad\AppData\Local\Programs\Python\Python311\Lib\socket.py", line 961, in getaddrinfo
    for res in _socket.getaddrinfo(host, port, family, type, proto, flags):
               ^^^^^^^^^^^^^^^^^^^^^^^^^^^^^^^^^^^^^^^^^^^^^^^^^^^^^^^^^^^
socket.gaierror: [Errno 11001] getaddrinfo failed
Bad Request: /register/
Internal Server Error: /register/
Traceback (most recent call last):
  File "C:\home\React\djnago_rest_framework\Final_project4_backend\venv\Lib\site-packages\django\core\handlers\exception.py", line 55, in inner
    response = get_response(request)
               ^^^^^^^^^^^^^^^^^^^^^
  File "C:\home\React\djnago_rest_framework\Final_project4_backend\venv\Lib\site-packages\django\core\handlers\base.py", line 197, in _get_response
    response = wrapped_callback(request, *callback_args, **callback_kwargs)
               ^^^^^^^^^^^^^^^^^^^^^^^^^^^^^^^^^^^^^^^^^^^^^^^^^^^^^^^^^^^^
  File "C:\home\React\djnago_rest_framework\Final_project4_backend\venv\Lib\site-packages\django\views\decorators\csrf.py", line 65, in _view_wrapper
    return view_func(request, *args, **kwargs)
           ^^^^^^^^^^^^^^^^^^^^^^^^^^^^^^^^^^^
  File "C:\home\React\djnago_rest_framework\Final_project4_backend\venv\Lib\site-packages\django\views\generic\base.py", line 104, in view
    return self.dispatch(request, *args, **kwargs)
           ^^^^^^^^^^^^^^^^^^^^^^^^^^^^^^^^^^^^^^^
  File "C:\home\React\djnago_rest_framework\Final_project4_backend\venv\Lib\site-packages\rest_framework\views.py", line 509, in dispatch
    response = self.handle_exception(exc)
               ^^^^^^^^^^^^^^^^^^^^^^^^^^
  File "C:\home\React\djnago_rest_framework\Final_project4_backend\venv\Lib\site-packages\rest_framework\views.py", line 469, in handle_exception
    self.raise_uncaught_exception(exc)
  File "C:\home\React\djnago_rest_framework\Final_project4_backend\venv\Lib\site-packages\rest_framework\views.py", line 480, in raise_uncaught_exception
    raise exc
  File "C:\home\React\djnago_rest_framework\Final_project4_backend\venv\Lib\site-packages\rest_framework\views.py", line 506, in dispatch
    response = handler(request, *args, **kwargs)
               ^^^^^^^^^^^^^^^^^^^^^^^^^^^^^^^^^
  File "C:\home\React\djnago_rest_framework\Final_project4_backend\two_factor_auth_project\auth_app\views.py", line 32, in post
    send_mail(
  File "C:\home\React\djnago_rest_framework\Final_project4_backend\venv\Lib\site-packages\django\core\mail\__init__.py", line 88, in send_mail
    return mail.send()
           ^^^^^^^^^^^
  File "C:\home\React\djnago_rest_framework\Final_project4_backend\venv\Lib\site-packages\django\core\mail\message.py", line 300, in send
    return self.get_connection(fail_silently).send_messages([self])
           ^^^^^^^^^^^^^^^^^^^^^^^^^^^^^^^^^^^^^^^^^^^^^^^^^^^^^^^^
  File "C:\home\React\djnago_rest_framework\Final_project4_backend\venv\Lib\site-packages\django\core\mail\backends\smtp.py", line 128, in send_messages
    new_conn_created = self.open()
                       ^^^^^^^^^^^
  File "C:\home\React\djnago_rest_framework\Final_project4_backend\venv\Lib\site-packages\django\core\mail\backends\smtp.py", line 86, in open
    self.connection = self.connection_class(
                      ^^^^^^^^^^^^^^^^^^^^^^
  File "C:\Users\bobad\AppData\Local\Programs\Python\Python311\Lib\smtplib.py", line 255, in __init__
    (code, msg) = self.connect(host, port)
                  ^^^^^^^^^^^^^^^^^^^^^^^^
  File "C:\Users\bobad\AppData\Local\Programs\Python\Python311\Lib\smtplib.py", line 341, in connect
    self.sock = self._get_socket(host, port, self.timeout)
                ^^^^^^^^^^^^^^^^^^^^^^^^^^^^^^^^^^^^^^^^^^
  File "C:\Users\bobad\AppData\Local\Programs\Python\Python311\Lib\smtplib.py", line 312, in _get_socket
    return socket.create_connection((host, port), timeout,
           ^^^^^^^^^^^^^^^^^^^^^^^^^^^^^^^^^^^^^^^^^^^^^^^
  File "C:\Users\bobad\AppData\Local\Programs\Python\Python311\Lib\socket.py", line 826, in create_connection
    for res in getaddrinfo(host, port, 0, SOCK_STREAM):
               ^^^^^^^^^^^^^^^^^^^^^^^^^^^^^^^^^^^^^^^
  File "C:\Users\bobad\AppData\Local\Programs\Python\Python311\Lib\socket.py", line 961, in getaddrinfo
    for res in _socket.getaddrinfo(host, port, family, type, proto, flags):
               ^^^^^^^^^^^^^^^^^^^^^^^^^^^^^^^^^^^^^^^^^^^^^^^^^^^^^^^^^^^
socket.gaierror: [Errno 11001] getaddrinfo failed
Bad Request: /register/
Bad Request: /register/
Internal Server Error: /register/
Traceback (most recent call last):
  File "C:\home\React\djnago_rest_framework\Final_project4_backend\venv\Lib\site-packages\django\core\handlers\exception.py", line 55, in inner
    response = get_response(request)
               ^^^^^^^^^^^^^^^^^^^^^
  File "C:\home\React\djnago_rest_framework\Final_project4_backend\venv\Lib\site-packages\django\core\handlers\base.py", line 197, in _get_response
    response = wrapped_callback(request, *callback_args, **callback_kwargs)
               ^^^^^^^^^^^^^^^^^^^^^^^^^^^^^^^^^^^^^^^^^^^^^^^^^^^^^^^^^^^^
  File "C:\home\React\djnago_rest_framework\Final_project4_backend\venv\Lib\site-packages\django\views\decorators\csrf.py", line 65, in _view_wrapper
    return view_func(request, *args, **kwargs)
           ^^^^^^^^^^^^^^^^^^^^^^^^^^^^^^^^^^^
  File "C:\home\React\djnago_rest_framework\Final_project4_backend\venv\Lib\site-packages\django\views\generic\base.py", line 104, in view
    return self.dispatch(request, *args, **kwargs)
           ^^^^^^^^^^^^^^^^^^^^^^^^^^^^^^^^^^^^^^^
  File "C:\home\React\djnago_rest_framework\Final_project4_backend\venv\Lib\site-packages\rest_framework\views.py", line 509, in dispatch
    response = self.handle_exception(exc)
               ^^^^^^^^^^^^^^^^^^^^^^^^^^
  File "C:\home\React\djnago_rest_framework\Final_project4_backend\venv\Lib\site-packages\rest_framework\views.py", line 469, in handle_exception
    self.raise_uncaught_exception(exc)
  File "C:\home\React\djnago_rest_framework\Final_project4_backend\venv\Lib\site-packages\rest_framework\views.py", line 480, in raise_uncaught_exception
    raise exc
  File "C:\home\React\djnago_rest_framework\Final_project4_backend\venv\Lib\site-packages\rest_framework\views.py", line 506, in dispatch
    response = handler(request, *args, **kwargs)
               ^^^^^^^^^^^^^^^^^^^^^^^^^^^^^^^^^
  File "C:\home\React\djnago_rest_framework\Final_project4_backend\two_factor_auth_project\auth_app\views.py", line 32, in post
    send_mail(
  File "C:\home\React\djnago_rest_framework\Final_project4_backend\venv\Lib\site-packages\django\core\mail\__init__.py", line 88, in send_mail
    return mail.send()
           ^^^^^^^^^^^
  File "C:\home\React\djnago_rest_framework\Final_project4_backend\venv\Lib\site-packages\django\core\mail\message.py", line 300, in send
    return self.get_connection(fail_silently).send_messages([self])
           ^^^^^^^^^^^^^^^^^^^^^^^^^^^^^^^^^^^^^^^^^^^^^^^^^^^^^^^^
  File "C:\home\React\djnago_rest_framework\Final_project4_backend\venv\Lib\site-packages\django\core\mail\backends\smtp.py", line 128, in send_messages
    new_conn_created = self.open()
                       ^^^^^^^^^^^
  File "C:\home\React\djnago_rest_framework\Final_project4_backend\venv\Lib\site-packages\django\core\mail\backends\smtp.py", line 86, in open
    self.connection = self.connection_class(
                      ^^^^^^^^^^^^^^^^^^^^^^
  File "C:\Users\bobad\AppData\Local\Programs\Python\Python311\Lib\smtplib.py", line 255, in __init__
    (code, msg) = self.connect(host, port)
                  ^^^^^^^^^^^^^^^^^^^^^^^^
  File "C:\Users\bobad\AppData\Local\Programs\Python\Python311\Lib\smtplib.py", line 341, in connect
    self.sock = self._get_socket(host, port, self.timeout)
                ^^^^^^^^^^^^^^^^^^^^^^^^^^^^^^^^^^^^^^^^^^
  File "C:\Users\bobad\AppData\Local\Programs\Python\Python311\Lib\smtplib.py", line 312, in _get_socket
    return socket.create_connection((host, port), timeout,
           ^^^^^^^^^^^^^^^^^^^^^^^^^^^^^^^^^^^^^^^^^^^^^^^
  File "C:\Users\bobad\AppData\Local\Programs\Python\Python311\Lib\socket.py", line 826, in create_connection
    for res in getaddrinfo(host, port, 0, SOCK_STREAM):
               ^^^^^^^^^^^^^^^^^^^^^^^^^^^^^^^^^^^^^^^
  File "C:\Users\bobad\AppData\Local\Programs\Python\Python311\Lib\socket.py", line 961, in getaddrinfo
    for res in _socket.getaddrinfo(host, port, family, type, proto, flags):
               ^^^^^^^^^^^^^^^^^^^^^^^^^^^^^^^^^^^^^^^^^^^^^^^^^^^^^^^^^^^
socket.gaierror: [Errno 11001] getaddrinfo failed
Bad Request: /register/
Not Found: /
Not Found: /favicon.ico
Internal Server Error: /verify_email/
Traceback (most recent call last):
  File "C:\home\React\djnago_rest_framework\Final_project4_backend\venv\Lib\site-packages\django\core\handlers\exception.py", line 55, in inner
    response = get_response(request)
               ^^^^^^^^^^^^^^^^^^^^^
  File "C:\home\React\djnago_rest_framework\Final_project4_backend\venv\Lib\site-packages\django\core\handlers\base.py", line 197, in _get_response
    response = wrapped_callback(request, *callback_args, **callback_kwargs)
               ^^^^^^^^^^^^^^^^^^^^^^^^^^^^^^^^^^^^^^^^^^^^^^^^^^^^^^^^^^^^
  File "C:\home\React\djnago_rest_framework\Final_project4_backend\venv\Lib\site-packages\django\views\decorators\csrf.py", line 65, in _view_wrapper
    return view_func(request, *args, **kwargs)
           ^^^^^^^^^^^^^^^^^^^^^^^^^^^^^^^^^^^
  File "C:\home\React\djnago_rest_framework\Final_project4_backend\venv\Lib\site-packages\django\views\generic\base.py", line 104, in view
    return self.dispatch(request, *args, **kwargs)
           ^^^^^^^^^^^^^^^^^^^^^^^^^^^^^^^^^^^^^^^
  File "C:\home\React\djnago_rest_framework\Final_project4_backend\venv\Lib\site-packages\rest_framework\views.py", line 511, in dispatch
    self.response = self.finalize_response(request, response, *args, **kwargs)
                    ^^^^^^^^^^^^^^^^^^^^^^^^^^^^^^^^^^^^^^^^^^^^^^^^^^^^^^^^^^
  File "C:\home\React\djnago_rest_framework\Final_project4_backend\venv\Lib\site-packages\rest_framework\views.py", line 423, in finalize_response
    assert isinstance(response, HttpResponseBase), (
AssertionError: Expected a `Response`, `HttpResponse` or `StreamingHttpResponse` to be returned from the view, but received a `<class 'NoneType'>`
Internal Server Error: /verify_email/
Traceback (most recent call last):
  File "C:\home\React\djnago_rest_framework\Final_project4_backend\venv\Lib\site-packages\django\core\handlers\exception.py", line 55, in inner
    response = get_response(request)
               ^^^^^^^^^^^^^^^^^^^^^
  File "C:\home\React\djnago_rest_framework\Final_project4_backend\venv\Lib\site-packages\django\core\handlers\base.py", line 197, in _get_response
    response = wrapped_callback(request, *callback_args, **callback_kwargs)
               ^^^^^^^^^^^^^^^^^^^^^^^^^^^^^^^^^^^^^^^^^^^^^^^^^^^^^^^^^^^^
  File "C:\home\React\djnago_rest_framework\Final_project4_backend\venv\Lib\site-packages\django\views\decorators\csrf.py", line 65, in _view_wrapper
    return view_func(request, *args, **kwargs)
           ^^^^^^^^^^^^^^^^^^^^^^^^^^^^^^^^^^^
  File "C:\home\React\djnago_rest_framework\Final_project4_backend\venv\Lib\site-packages\django\views\generic\base.py", line 104, in view
    return self.dispatch(request, *args, **kwargs)
           ^^^^^^^^^^^^^^^^^^^^^^^^^^^^^^^^^^^^^^^
  File "C:\home\React\djnago_rest_framework\Final_project4_backend\venv\Lib\site-packages\rest_framework\views.py", line 511, in dispatch
    self.response = self.finalize_response(request, response, *args, **kwargs)
                    ^^^^^^^^^^^^^^^^^^^^^^^^^^^^^^^^^^^^^^^^^^^^^^^^^^^^^^^^^^
  File "C:\home\React\djnago_rest_framework\Final_project4_backend\venv\Lib\site-packages\rest_framework\views.py", line 423, in finalize_response
    assert isinstance(response, HttpResponseBase), (
AssertionError: Expected a `Response`, `HttpResponse` or `StreamingHttpResponse` to be returned from the view, but received a `<class 'NoneType'>`
Internal Server Error: /verify_email/
Traceback (most recent call last):
  File "C:\home\React\djnago_rest_framework\Final_project4_backend\two_factor_auth_project\auth_app\views.py", line 50, in get
    payload = jwt.decode(token, settings.SECRET_KEY)
              ^^^^^^^^^^^^^^^^^^^^^^^^^^^^^^^^^^^^^^
  File "C:\home\React\djnago_rest_framework\Final_project4_backend\venv\Lib\site-packages\jwt\api_jwt.py", line 210, in decode
    decoded = self.decode_complete(
              ^^^^^^^^^^^^^^^^^^^^^
  File "C:\home\React\djnago_rest_framework\Final_project4_backend\venv\Lib\site-packages\jwt\api_jwt.py", line 147, in decode_complete
    raise DecodeError(
jwt.exceptions.DecodeError: It is required that you pass in a value for the "algorithms" argument when calling decode().

During handling of the above exception, another exception occurred:

Traceback (most recent call last):
  File "C:\home\React\djnago_rest_framework\Final_project4_backend\venv\Lib\site-packages\django\core\handlers\exception.py", line 55, in inner
    response = get_response(request)
               ^^^^^^^^^^^^^^^^^^^^^
  File "C:\home\React\djnago_rest_framework\Final_project4_backend\venv\Lib\site-packages\django\core\handlers\base.py", line 197, in _get_response
    response = wrapped_callback(request, *callback_args, **callback_kwargs)
               ^^^^^^^^^^^^^^^^^^^^^^^^^^^^^^^^^^^^^^^^^^^^^^^^^^^^^^^^^^^^
  File "C:\home\React\djnago_rest_framework\Final_project4_backend\venv\Lib\site-packages\django\views\decorators\csrf.py", line 65, in _view_wrapper
    return view_func(request, *args, **kwargs)
           ^^^^^^^^^^^^^^^^^^^^^^^^^^^^^^^^^^^
  File "C:\home\React\djnago_rest_framework\Final_project4_backend\venv\Lib\site-packages\django\views\generic\base.py", line 104, in view
    return self.dispatch(request, *args, **kwargs)
           ^^^^^^^^^^^^^^^^^^^^^^^^^^^^^^^^^^^^^^^
  File "C:\home\React\djnago_rest_framework\Final_project4_backend\venv\Lib\site-packages\rest_framework\views.py", line 509, in dispatch
    response = self.handle_exception(exc)
               ^^^^^^^^^^^^^^^^^^^^^^^^^^
  File "C:\home\React\djnago_rest_framework\Final_project4_backend\venv\Lib\site-packages\rest_framework\views.py", line 469, in handle_exception
    self.raise_uncaught_exception(exc)
  File "C:\home\React\djnago_rest_framework\Final_project4_backend\venv\Lib\site-packages\rest_framework\views.py", line 480, in raise_uncaught_exception
    raise exc
  File "C:\home\React\djnago_rest_framework\Final_project4_backend\venv\Lib\site-packages\rest_framework\views.py", line 506, in dispatch
    response = handler(request, *args, **kwargs)
               ^^^^^^^^^^^^^^^^^^^^^^^^^^^^^^^^^
  File "C:\home\React\djnago_rest_framework\Final_project4_backend\two_factor_auth_project\auth_app\views.py", line 58, in get
    return Response(data={'error': identifire.message}, status=status.HTTP_400_BAD_REQUEST)
                                   ^^^^^^^^^^^^^^^^^^
AttributeError: 'DecodeError' object has no attribute 'message'
Internal Server Error: /verify_email/
Traceback (most recent call last):
  File "C:\home\React\djnago_rest_framework\Final_project4_backend\two_factor_auth_project\auth_app\views.py", line 50, in get
    payload = jwt.decode(token, settings.SECRET_KEY)
              ^^^^^^^^^^^^^^^^^^^^^^^^^^^^^^^^^^^^^^
  File "C:\home\React\djnago_rest_framework\Final_project4_backend\venv\Lib\site-packages\jwt\api_jwt.py", line 210, in decode
    decoded = self.decode_complete(
              ^^^^^^^^^^^^^^^^^^^^^
  File "C:\home\React\djnago_rest_framework\Final_project4_backend\venv\Lib\site-packages\jwt\api_jwt.py", line 147, in decode_complete
    raise DecodeError(
jwt.exceptions.DecodeError: It is required that you pass in a value for the "algorithms" argument when calling decode().

During handling of the above exception, another exception occurred:

Traceback (most recent call last):
  File "C:\home\React\djnago_rest_framework\Final_project4_backend\venv\Lib\site-packages\django\core\handlers\exception.py", line 55, in inner
    response = get_response(request)
               ^^^^^^^^^^^^^^^^^^^^^
  File "C:\home\React\djnago_rest_framework\Final_project4_backend\venv\Lib\site-packages\django\core\handlers\base.py", line 197, in _get_response
    response = wrapped_callback(request, *callback_args, **callback_kwargs)
               ^^^^^^^^^^^^^^^^^^^^^^^^^^^^^^^^^^^^^^^^^^^^^^^^^^^^^^^^^^^^
  File "C:\home\React\djnago_rest_framework\Final_project4_backend\venv\Lib\site-packages\django\views\decorators\csrf.py", line 65, in _view_wrapper
    return view_func(request, *args, **kwargs)
           ^^^^^^^^^^^^^^^^^^^^^^^^^^^^^^^^^^^
  File "C:\home\React\djnago_rest_framework\Final_project4_backend\venv\Lib\site-packages\django\views\generic\base.py", line 104, in view
    return self.dispatch(request, *args, **kwargs)
           ^^^^^^^^^^^^^^^^^^^^^^^^^^^^^^^^^^^^^^^
  File "C:\home\React\djnago_rest_framework\Final_project4_backend\venv\Lib\site-packages\rest_framework\views.py", line 509, in dispatch
    response = self.handle_exception(exc)
               ^^^^^^^^^^^^^^^^^^^^^^^^^^
  File "C:\home\React\djnago_rest_framework\Final_project4_backend\venv\Lib\site-packages\rest_framework\views.py", line 469, in handle_exception
    self.raise_uncaught_exception(exc)
  File "C:\home\React\djnago_rest_framework\Final_project4_backend\venv\Lib\site-packages\rest_framework\views.py", line 480, in raise_uncaught_exception
    raise exc
  File "C:\home\React\djnago_rest_framework\Final_project4_backend\venv\Lib\site-packages\rest_framework\views.py", line 506, in dispatch
    response = handler(request, *args, **kwargs)
               ^^^^^^^^^^^^^^^^^^^^^^^^^^^^^^^^^
  File "C:\home\React\djnago_rest_framework\Final_project4_backend\two_factor_auth_project\auth_app\views.py", line 58, in get
    return Response(data={'error': identifire.message}, status=status.HTTP_400_BAD_REQUEST)
                                   ^^^^^^^^^^^^^^^^^^
AttributeError: 'DecodeError' object has no attribute 'message'
Bad Request: /verify_email/
Bad Request: /verify_email/
Bad Request: /verify_email/
